<?xml version="1.0"?>
<robot xmlns:xacro="http://www.ros.org/wiki/xacro" >

    <xacro:include filename="inertial_macros.xacro"/>

    <material name="white">
        <color rgba="1 1 1 1" />
    </material>

    <material name="orange">
        <color rgba="1 0.3 0.1 1"/>
    </material>

    <material name="blue">
        <color rgba="0.2 0.2 1 1"/>
    </material>

    <material name="black">
        <color rgba="0 0 0 1"/>
    </material>

    <material name="wood">
        <color rgba="0.76 0.6 0.42 1"/>
    </material>

    <material name="red">
        <color rgba="1 0 0 1"/>
    </material>

    <!-- BASE LINK -->

    <link name="base_link">

    </link>

    <!-- BASE_FOOTPRINT LINK -->

    <joint name="base_footprint_joint" type="fixed">
        <parent link="base_link"/>
        <child link="base_footprint"/>
        <origin xyz="0 0 0" rpy="0 0 0"/>
    </joint>

    <link name="base_footprint">
    </link>
    

    <!-- CHASSIS LINK -->

    <joint name="chassis_joint" type="fixed">
        <parent link="base_link"/>
        <child link="chassis"/>
        <origin xyz="-0.15 0 0"/>
    </joint>

    <link name="chassis">
        <visual>
            <origin xyz="0.15 0 0.075"/>
            <geometry>
                <cylinder radius="0.2" length="0.62"/>
            </geometry>
            <material name="wood"/>
        </visual>
        <collision>
            <origin xyz="0.15 0 0.075"/>
            <geometry>
                <cylinder radius="0.2" length="0.62"/>
            </geometry>
        </collision>
        <xacro:inertial_cylinder mass="0.5" length="0.62" radius="0.1">
            <origin xyz="0.15 0 0.075" rpy="0 0 0"/>
        </xacro:inertial_cylinder>
    </link>
    <gazebo reference="chassis">
        <material>Gazebo/Wood</material>
    </gazebo>
    
    <!-- LEFT WHEEL LINK -->

    <joint name="left_wheel_joint" type="continuous">
        <parent link="base_link"/>
        <child link="left_wheel"/>
        <origin xyz="-0.0001 0.178 -0.28" rpy="-${pi/2} 0 0" />
        <axis xyz="0 0 1"/>
    </joint>

    <link name="left_wheel">
        <visual>
            <geometry>
                <cylinder radius="0.05" length="0.05"/>
            </geometry>
            <material name="blue"/>
        </visual>
        <collision>
            <geometry>
                <cylinder radius="0.05" length="0.05"/>
            </geometry>
        </collision>
        <xacro:inertial_cylinder mass="0.1" length="0.05" radius="0.05">
            <origin xyz="0 0 0" rpy="0 0 0"/>
        </xacro:inertial_cylinder>
    </link>
    <gazebo reference="left_wheel">
        <material>Gazebo/Blue</material>
    </gazebo>
    

    <!-- RIGHT WHEEL LINK -->

    <joint name="right_wheel_joint" type="continuous">
        <parent link="base_link"/>
        <child link="right_wheel"/>
        <origin xyz="-0.0001 -0.178 -0.28" rpy="${pi/2} 0 0" />
        <axis xyz="0 0 -1"/>
    </joint>

    <link name="right_wheel">
        <visual>
            <geometry>
                <cylinder radius="0.05" length="0.05"/>
            </geometry>
            <material name="blue"/>
        </visual>
        <collision>
            <geometry>
                <cylinder radius="0.05" length="0.05"/>
            </geometry>
        </collision>
        <xacro:inertial_cylinder mass="0.1" length="0.05" radius="0.05">
            <origin xyz="0 0 0" rpy="0 0 0"/>
        </xacro:inertial_cylinder>
    </link>
    <gazebo reference="right_wheel">
        <material>Gazebo/Blue</material>
    </gazebo>

    <!-- CASTER WHEEL LINK -->

    <joint name="caster_wheel_joint1" type="fixed">
        <parent link="chassis"/>
        <child link="caster_wheel1"/>
        <origin xyz="0.3 0 -0.27999"/>
    </joint>


    <link name="caster_wheel1">
        <visual>
            <geometry>
                <sphere radius="0.049"/>
            </geometry>
            <material name="black"/>
        </visual>
        <collision>
            <geometry>
                <sphere radius="0.049"/>
            </geometry>
        </collision>
        <xacro:inertial_sphere mass="0.1" radius="0.049">
            <origin xyz="0 0 0" rpy="0 0 0"/>
        </xacro:inertial_sphere>
    </link>
    <gazebo reference="caster_wheel1">
        <material>Gazebo/Black</material>
        <mu1>0.0</mu1>
        <mu2>0.0</mu2>
        <kp>1000000.0</kp>
        <kd>100.0</kd>
        <minDepth>0.001</minDepth>
        <maxVel>1.0</maxVel>
    </gazebo>


     <!-- CASTER WHEEL LINK 2 -->

     <joint name="caster_wheel_joint2" type="fixed">
        <parent link="chassis"/>
        <child link="caster_wheel2"/>
        <origin xyz="0.01 0 -0.27999"/>
    </joint>


    <link name="caster_wheel2">
        <visual>
            <geometry>
                <sphere radius="0.049"/>
            </geometry>
            <material name="black"/>
        </visual>
        <collision>
            <geometry>
                <sphere radius="0.049"/>
            </geometry>
        </collision>
        <xacro:inertial_sphere mass="0.1" radius="0.049">
            <origin xyz="0 0 0" rpy="0 0 0"/>
        </xacro:inertial_sphere>
    </link>
    <gazebo reference="caster_wheel2">
        <material>Gazebo/Black</material>
        <mu1>0.0</mu1>
        <mu2>0.0</mu2>
        <kp>1000000.0</kp>
        <kd>100.0</kd>
        <minDepth>0.001</minDepth>
        <maxVel>1.0</maxVel>
    </gazebo>
    
</robot>